Workbook

Sheet map
A1: Legacy | B1: Vuln ID | C1: Rule ID | D1: Legacy | E1: Legacy
A2: V-63319 | B2: V-220697 | C2: SV-220697r569187_rule | D2: V-63319 | E2: SV-77809
A3: V-63323 | B3: V-220698 | C3: SV-220698r569187_rule | D3: V-63323 | E3: SV-77813
A4: V-77083 | B4: V-220699 | C4: SV-220699r569187_rule | D4: V-77083 | E4: SV-91779
A5: V-77085 | B5: V-220700 | C5: SV-220700r569187_rule | D5: V-77085 | E5: SV-91781
A6: V-63343 | B6: V-220701 | C6: SV-220701r569187_rule | D6: V-63343 | E6: SV-77833
A7: V-63337 | B7: V-220702 | C7: SV-220702r569228_rule | D7: V-63337 | E7: SV-77827
A8: V-94859 | B8: V-220703 | C8: SV-220703r569288_rule | D8: V-94859 | E8: SV-104689
A9: V-94861 | B9: V-220704 | C9: SV-220704r569290_rule | D9: V-94861 | E9: SV-104691
A10: V-63345 | B10: V-220705 | C10: SV-220705r569187_rule | D10: V-63345 | E10: SV-77835
A11: V-63349 | B11: V-220706 | C11: SV-220706r646212_rule | D11: V-63349 | E11: SV-77839
A12: V-63351 | B12: V-220707 | C12: SV-220707r569187_rule | D12: V-63351 | E12: SV-77841
... A285: V-63941 | B285: V-220983 | C285: SV-220983r569187_rule | D285: V-63941 | E285: SV-78431
B286: V-230220 | C286: SV-230220r569300_rule

Sheet Sheet3
A1: Legacy | B1: Vuln ID | C1: Vuln ID | D1: Rule ID | E1: Rule Title | F1: Discussion | G1: Check Content | H1: Fix Text | I1: STIG | J1: Status | K1: Fully Qualified Domain Name | L1: NIST SP 800-53 Revision 4 References | M1: Legacy | N1: Legacy | O1: Legacy | P1: vl
A2: V-100093 | B2: 220793 | C2: V-220793 | D2: SV-220793r569187_rule | E2: Windows 10 must cover or disable the built-in or attached camera when not in use. | F2: It is detrimental for operating systems to provide, or install by default, functionality exceeding requirements or mission objectives. These unnecessary capabilities or services are often overlooked and therefore may remain unsecured. They increase the risk to the platform by providing additional attack vectors. Failing to disconnect from collaborative computing devices (i.e. cameras) can result in subsequent compromises of organizational information. Providing easy methods to physically disconnect from such devices after a collaborative computing session helps to ensure that participants actually carry out the disconnect activity without having to go through complex and tedious procedures. Satisfies: SRG-OS-000095-GPOS-00049, SRG-OS-000370-GPOS-00155 | G2: If the device or operating system does not have a camera installed, this requirement is not applicable. This requirement is not applicable to mobile devices (smartphones and tablets), where the use of the camera is a local AO decision. This requirement is not applicable to dedicated VTC suites located in approved VTC locations that are centrally managed. For an external camera, if there is not a method for the operator to manually disconnect camera at the end of collaborative computing sessions, this is a finding. For a built-in camera, the camera must be protected by a camera cover (e.g. laptop camera cover slide) when not in use. If the built-in camera is not protected with a camera cover, or if the built-in camera is not disabled in the bios, this is a finding. If the camera is not disconnected or covered, the following registry entry is required: Registry Hive: HKEY_LOCAL_MACHINE RegistryPath\SOFTWARE\Microsoft\Windows\CurrentVersion\CapabilityAccessManager\ConsentStore\webcam Value Name: Deny If "Value Name" is set to a value other than "Deny" and the collaborative computing device has not been authorized for use, this is a finding. | H2: If the camera is not disconnected or covered, the following registry entry is required. Registry Hive: HKEY_LOCAL_MACHINE RegistryPath\SOFTWARE\Microsoft\Windows\CurrentVersion\CapabilityAccessManager\ConsentStore\webcam Value Name: Deny | I2: Windows 10 Security Technical Implementation Guide :: Version 2, Release: 2 Benchmark Date: 04 May 2021 | J2: Not Reviewed | L2: CM-7 a | M2: V-100093; SV-109197 | N2: V-100093 | O2: SV-109197 | P2: V-100093
A3: V-63323 | B3: 220698 | C3: V-220698 | D3: SV-220698r569187_rule | E3: Windows 10 domain-joined systems must have a Trusted Platform Module (TPM) enabled and ready for use. | F3: Credential Guard uses virtualization based security to protect information that could be used in credential theft attacks if compromised. There are a number of system requirements that must be met in order for Credential Guard to be configured and enabled properly. Without a TPM enabled and ready for use, Credential Guard keys are stored in a less secure method using software. | G3: Verify domain-joined systems have a TPM enabled and ready for use. For standalone systems, this is NA. Virtualization based security, including Credential Guard, currently cannot be implemented in virtual desktop implementations (VDI) due to specific supporting requirements including a TPM, UEFI with Secure Boot, and the capability to run the Hyper-V feature within the virtual desktop. For VDIs where the virtual desktop instance is deleted or refreshed upon logoff, this is NA. Verify the system has a TPM and is ready for use. Run "tpm.msc". Review the sections in the center pane. "Status" must indicate it has been configured with a message such as "The TPM is ready for use" or "The TPM is on and ownership has been taken". TPM Manufacturer Information - Specific Version = 2.0 or 1.2 If a TPM is not found or is not ready for use, this is a finding. | H3: For standalone systems, this is NA. Virtualization based security, including Credential Guard, currently cannot be implemented in virtual desktop implementations (VDI) due to specific supporting requirements including a TPM, UEFI with Secure Boot, and the capability to run the Hyper-V feature within the virtual desktop. For VDIs where the virtual desktop instance is deleted or refreshed upon logoff, this is NA. Ensure domain-joined systems must have a Trusted Platform Module (TPM) that is configured for use. (Versions 2.0 or 1.2 support Credential Guard.) The TPM must be enabled in the firmware. Run "tpm.msc" for configuration options in Windows. | I3: Windows 10 Security Technical Implementation Guide :: Version 2, Release: 2 Benchmark Date: 04 May 2021 | J3: Not Reviewed | L3: CM-6 b | M3: V-63323; SV-77813 | N3: V-63323 | O3: SV-77813 | P3: V-63323
A4: V-63345 | B4: 220705 | C4: V-220705 | D4: SV-220705r569187_rule | E4: The operating system must employ a deny-all, permit-by-exception policy to allow the execution of authorized software programs. | F4: Utilizing a whitelist provides a configuration management method for allowing the execution of only authorized software. Using only authorized software decreases risk by limiting the number of potential vulnerabilities. The organization must identify authorized software programs and only permit execution of authorized software. The process used to identify software programs that are authorized to execute on organizational information systems is commonly referred to as whitelisting. | G4: This is applicable to unclassified systems; for other systems this is NA. Verify the operating system employs a deny-all, permit-by-exception policy to allow the execution of authorized software programs. This must include packaged apps such as the universals apps installed by default on systems. If an application whitelisting program is not in use on the system, this is a finding. Configuration of whitelisting applications will vary by the program. AppLocker is a whitelisting application built into Windows 10 Enterprise. A deny-by-default implementation is initiated by enabling any AppLocker rules within a category, only allowing what is specified by defined rules. If AppLocker is used, perform the following to view the configuration of AppLocker: Run "PowerShell". Execute the following command, substituting [c:\temp\file.xml] with a location and file name appropriate for the system: Get-AppLockerPolicy -Effective -XML > c:\temp\file.xml This will produce an xml file with the effective settings that can be viewed in a browser or opened in a program such as Excel for review. Implementation guidance for AppLocker is available in the NSA paper "Application Whitelisting using Microsoft AppLocker" at the following link: https://www.iad.gov/iad/library/ia-guidance/tech-briefs/application-whitelisting-using-microsoft-applocker.cfm | H4: Configure an application whitelisting program to employ a deny-all, permit-by-exception policy to allow the execution of authorized software programs. Configuration of whitelisting applications will vary by the program. AppLocker is a whitelisting application built into Windows 10 Enterprise. If AppLocker is used, it is configured through group policy in Computer Configuration >> Windows Settings >> Security Settings >> Application Control Policies >> AppLocker. Implementation guidance for AppLocker is available in the NSA paper "Application Whitelisting using Microsoft AppLocker" at the following link: https://www.iad.gov/iad/library/ia-guidance/tech-briefs/application-whitelisting-using-microsoft-applocker.cfm | I4: Windows 10 Security Technical Implementation Guide :: Version 2, Release: 2 Benchmark Date: 04 May 2021 | J4: Not Reviewed | L4: CM-7 (5) (b) | M4: V-63345; SV-77835 | N4: V-63345 | O4: SV-77835 | P4: V-63345
A5: V-63351 | B5: 220707 | C5: V-220707 | D5: SV-220707r569187_rule | E5: The Windows 10 system must use an anti-virus program. | F5: Malicious software can establish a base on individual desktops and servers. Employing an automated mechanism to detect this type of software will aid in elimination of the software from the operating system. | G5: Verify an anti-virus solution is installed on the system and in use. The anti-virus solution may be bundled with an approved host-based security solution. Verify if Windows Defender is in use or enabled: Open "PowerShell". Enter â€œget-service | where {$_.DisplayName -Like "*Defender*"} | Select Status,DisplayNameâ€ Verify third-party antivirus is in use or enabled: Open "PowerShell". Enter â€œget-service | where {$_.DisplayName -Like "*mcafee*"} | Select Status,DisplayNameâ€ Enter â€œget-service | where {$_.DisplayName -Like "*symantec*"} | Select Status,DisplayNameâ€ If there is no anti-virus solution installed on the system, this is a finding. | H5: If no anti-virus software is in use, install Windows Defender or a third-party anti-virus solution. | I5: Windows 10 Security Technical Implementation Guide :: Version 2, Release: 2 Benchmark Date: 04 May 2021 | J5: Not Reviewed | L5: CM-6 b | M5: V-63351; SV-77841 | N5: V-63351 | O5: SV-77841 | P5: V-63351
A6: V-63355 | B6: 220709 | C6: V-220709 | D6: SV-220709r569187_rule | E6: Alternate operating systems must not be permitted on the same system. | F6: Allowing other operating systems to run on a secure system may allow security to be circumvented. | G6: Verify the system does not include other operating system installations. Run "Advanced System Settings". Select the "Advanced" tab. Click the "Settings" button in the "Startup and Recovery" section. If the drop-down list box "Default operating system:" shows any operating system other than Windows 10, this is a finding. | H6: Ensure Windows 10 is the only operating system on a device. Remove alternate operating systems. | I6: Windows 10 Security Technical Implementation Guide :: Version 2, Release: 2 Benchmark Date: 04 May 2021 | J6: Not Reviewed | L6: CM-6 b | M6: V-63355; SV-77845 | N6: V-63355 | O6: SV-77845 | P6: V-63355
A7: V-63357 | B7: 220710 | C7: V-220710 | D7: SV-220710r569187_rule | E7: Non system-created file shares on a system must limit access to groups that require it. | F7: Shares which provide network access, should not typically exist on a workstation except for system-created administrative shares, and could potentially expose sensitive information. If a share is necessary, share permissions, as well as NTFS permissions, must be reconfigured to give the minimum access to those accounts that require it. | G7: Non system-created shares should not typically exist on workstations. If only system-created shares exist on the system this is NA. Run "Computer Management". Navigate to System Tools >> Shared Folders >> Shares. If the only shares listed are "ADMIN$", "C$" and "IPC$", this is NA. (Selecting Properties for system-created shares will display a message that it has been shared for administrative purposes.) Right click any non-system-created shares. Select "Properties". Select the "Share Permissions" tab. Verify the necessity of any shares found. If the file shares have not been reconfigured to restrict permissions to the specific groups or accounts that require access, this is a finding. Select the "Security" tab. If the NTFS permissions have not been reconfigured to restrict permissions to the specific groups or accounts that require access, this is a finding. | H7: If a non system-created share is required on a system, configure the share and NTFS permissions to limit access to the specific groups or accounts that require it. Remove any unnecessary non-system created shares. | I7: Windows 10 Security Technical Implementation Guide :: Version 2, Release: 2 Benchmark Date: 04 May 2021 | J7: Not Reviewed | L7: SC-4 | M7: V-63357; SV-77847 | N7: V-63357 | O7: SV-77847 | P7: V-63357
A8: V-63359 | B8: 220711 | C8: V-220711 | D8: SV-220711r569187_rule | E8: Unused accounts must be disabled or removed from the system after 35 days of inactivity. | F8: Outdated or unused accounts provide penetration points that may go undetected. Inactive accounts must be deleted if no longer necessary or, if still required, disable until needed. | G8: Run "PowerShell". Copy the lines below to the PowerShell window and enter. "([ADSI]('WinNT://{0}' -f $env:COMPUTERNAME)).Children | Where { $_.SchemaClassName -eq 'user' } | ForEach { $user = ([ADSI]$_.Path) $lastLogin = $user.Properties.LastLogin.Value $enabled = ($user.Properties.UserFlags.Value -band 0x2) -ne 0x2 if ($lastLogin -eq $null) { $lastLogin = 'Never' } Write-Host $user.Name $lastLogin $enabled }" This will return a list of local accounts with the account name, last logon, and if the account is enabled (True/False). For example: User1 10/31/2015 5:49:56 AM True Review the list to determine the finding validity for each account reported. Exclude the following accounts: Built-in administrator account (Disabled, SID ending in 500) Built-in guest account (Disabled, SID ending in 501) Built-in DefaultAccount (Disabled, SID ending in 503) Local administrator account If any enabled accounts have not been logged on to within the past 35 days, this is a finding. Inactive accounts that have been reviewed and deemed to be required must be documented with the ISSO. | H8: Regularly review local accounts and verify their necessity. Disable or delete any active accounts that have not been used in the last 35 days. | I8: Windows 10 Security Technical Implementation Guide :: Version 2, Release: 2 Benchmark Date: 04 May 2021 | J8: Not Reviewed | L8: IA-4 e | M8: V-63359; SV-77849 | N8: V-63359 | O8: SV-77849 | P8: V-63359
A9: V-63361 | B9: 220712 | C9: V-220712 | D9: SV-220712r569187_rule | E9: Only accounts responsible for the administration of a system must have Administrator rights on the system. | F9: An account that does not have Administrator duties must not have Administrator rights. Such rights would allow the account to bypass or modify required security restrictions on that machine and make it vulnerable to attack. System administrators must log on to systems only using accounts with the minimum level of authority necessary. For domain-joined workstations, the Domain Admins group must be replaced by a domain workstation administrator group (see V-36434 in the Active Directory Domain STIG). Restricting highly privileged accounts from the local Administrators group helps mitigate the risk of privilege escalation resulting from credential theft attacks. Standard user accounts must not be members of the local administrators group. | G9: Run "Computer Management". Navigate to System Tools >> Local Users and Groups >> Groups. Review the members of the Administrators group. Only the appropriate administrator groups or accounts responsible for administration of the system may be members of the group. For domain-joined workstations, the Domain Admins group must be replaced by a domain workstation administrator group. Standard user accounts must not be members of the local administrator group. If prohibited accounts are members of the local administrators group, this is a finding. The built-in Administrator account or other required administrative accounts would not be a finding. | H9: Configure the system to include only administrator groups or accounts that are responsible for the system in the local Administrators group. For domain-joined workstations, the Domain Admins group must be replaced by a domain workstation administrator group. Remove any standard user accounts. | I9: Windows 10 Security Technical Implementation Guide :: Version 2, Release: 2 Benchmark Date: 04 May 2021 | J9: Not Reviewed | L9: AC-6 (10) | M9: V-63361; SV-77851 | N9: V-63361 | O9: SV-77851 | P9: V-63361
A10: V-63363 | B10: 220713 | C10: V-220713 | D10: SV-220713r569187_rule | E10: Only accounts responsible for the backup operations must be members of the Backup Operators group. | F10: Backup Operators are able to read and write to any file in the system, regardless of the rights assigned to it. Backup and restore rights permit users to circumvent the file access restrictions present on NTFS disk drives for backup and restore purposes. Members of the Backup Operators group must have separate logon accounts for performing backup duties. | G10: Run "Computer Management". Navigate to System Tools >> Local Users and Groups >> Groups. Review the members of the Backup Operators group. If the group contains no accounts, this is not a finding. If the group contains any accounts, the accounts must be specifically for backup functions. If the group contains any standard user accounts used for performing normal user tasks, this is a finding. | H10: Create separate accounts for backup operations for users with this privilege. | I10: Windows 10 Security Technical Implementation Guide :: Version 2, Release: 2 Benchmark Date: 04 May 2021 | J10: Not Reviewed | L10: CM-6 b | M10: V-63363; SV-77853 | N10: V-63363 | O10: SV-77853 | P10: V-63363
A11: V-63367 | B11: 220715 | C11: V-220715 | D11: SV-220715r569187_rule | E11: Standard local user accounts must not exist on a system in a domain. | F11: To minimize potential points of attack, local user accounts, other than built-in accounts and local administrator accounts, must not exist on a workstation in a domain. Users must log onto workstations in a domain with their domain accounts. | G11: Run "Computer Management". Navigate to System Tools >> Local Users and Groups >> Users. If local users other than the accounts listed below exist on a workstation in a domain, this is a finding. Built-in Administrator account (Disabled) Built-in Guest account (Disabled) Built-in DefaultAccount (Disabled) Built-in defaultuser0 (Disabled) Built-in WDAGUtilityAccount (Disabled) Local administrator account(s) All of the built-in accounts may not exist on a system, depending on the Windows 10 version. | H11: Limit local user accounts on domain-joined systems. Remove any unauthorized local accounts. | I11: Windows 10 Security Technical Implementation Guide :: Version 2, Release: 2 Benchmark Date: 04 May 2021 | J11: Not Reviewed | L11: CM-6 b | M11: V-63367; SV-77857 | N11: V-63367 | O11: SV-77857 | P11: V-63367
A12: V-63371 | B12: 220716 | C12: V-220716 | D12: SV-220716r569187_rule | E12: Accounts must be configured to require password expiration. | F12: Passwords that do not expire increase exposure with a greater probability of being discovered or cracked. | G12: Run "Computer Management". Navigate to System Tools >> Local Users and Groups >> Users. Double click each active account. If "Password never expires" is selected for any account, this is a finding. | H12: Configure all passwords to expire. Run "Computer Management". Navigate to System Tools >> Local Users and Groups >> Users. Double click each active account. Ensure "Password never expires" is not checked on all active accounts. | I12: Windows 10 Security Technical Implementation Guide :: Version 2, Release: 2 Benchmark Date: 04 May 2021 | J12: Not Reviewed | L12: IA-5 (1) (d) | M12: V-63371; SV-77861 | N12: V-63371 | O12: SV-77861 | P12: V-63371
A13: V-63393 | B13: 220723 | C13: V-220723 | D13: SV-220723r569187_rule | E13: Software certificate installation files must be removed from Windows 10. | F13: Use of software certificates and their accompanying installation files for end users to access resources is less secure than the use of hardware-based certificates. | G13: Search all drives for *.p12 and *.pfx files. If any files with these extensions exist, this is a finding. This does not apply to server-based applications that have a requirement for .p12 certificate files (e.g., Oracle Wallet Manager) or Adobe PreFlight certificate files. Some applications create files with extensions of .p12 that are not certificate installation files. Removal of non-certificate installation files from systems is not required. These must be documented with the ISSO. | H13: Remove any certificate installation files (*.p12 and *.pfx) found on a system. Note: This does not apply to server-based applications that have a requirement for .p12 certificate files (e.g., Oracle Wallet Manager) or Adobe PreFlight certificate files. | I13: Windows 10 Security Technical Implementation Guide :: Version 2, Release: 2 Benchmark Date: 04 May 2021 | J13: Not Reviewed | L13: CM-6 b | M13: V-63393; SV-77883 | N13: V-63393 | O13: SV-77883 | P13: V-63393
... A23: V-76505 | B23: 220733 | C23: V-220733 | D23: SV-220733r569187_rule | E23: Orphaned security identifiers (SIDs) must be removed from user rights on Windows 10. | F23: Accounts or groups given rights on a system may show up as unresolved SIDs for various reasons including deletion of the accounts or groups. If the account or group objects are reanimated, there is a potential they may still have rights no longer intended. Valid domain accounts or groups may also show up as unresolved SIDs if a connection to the domain cannot be established for some reason. | G23: Review the effective User Rights setting in Local Group Policy Editor. Run "gpedit.msc". Navigate to Local Computer Policy >> Computer Configuration >> Windows Settings >> Security Settings >> Local Policies >> User Rights Assignment. Review each User Right listed for any unresolved SIDs to determine whether they are valid, such as due to being temporarily disconnected from the domain. (Unresolved SIDs have the format of "*S-1-â€¦".) If any unresolved SIDs exist and are not for currently valid accounts or groups, this is a finding. | H23: Remove any unresolved SIDs found in User Rights assignments and determined to not be for currently valid accounts or groups by removing the accounts or groups from the appropriate group policy. | I23: Windows 10 Security Technical Implementation Guide :: Version 2, Release: 2 Benchmark Date: 04 May 2021 | J23: Not Reviewed | L23: CM-6 b | M23: V-76505; SV-91201 | N23: V-76505 | O23: SV-91201 | P23: V-76505
A24: V-77085 | B24: 220700 | C24: V-220700 | D24: SV-220700r569187_rule | E24: Secure Boot must be enabled on Windows 10 systems. | F24: Secure Boot is a standard that ensures systems boot only to a trusted operating system. Secure Boot is required to support additional security features in Windows 10, including Virtualization Based Security and Credential Guard. If Secure Boot is turned off, these security features will not function. | G24: Some older systems may not have UEFI firmware. This is currently a CAT III; it will be raised in severity at a future date when broad support of Windows 10 hardware and firmware requirements are expected to be met. Devices that have UEFI firmware must have Secure Boot enabled. For virtual desktop implementations (VDIs) where the virtual desktop instance is deleted or refreshed upon logoff, this is NA. Run "System Information". Under "System Summary", if "Secure Boot State" does not display "On", this is finding. | H24: Enable Secure Boot in the system firmware. | I24: Windows 10 Security Technical Implementation Guide :: Version 2, Release: 2 Benchmark Date: 04 May 2021 | J24: Not Reviewed | L24: CM-6 b | M24: V-77085; SV-91781 | N24: V-77085 | O24: SV-91781 | P24: V-77085
A25: V-77091 | B25: 220873 | C25: V-220873 | D25: SV-220873r569187_rule | E25: Windows 10 Exploit Protection system-level mitigation, Data Execution Prevention (DEP), must be on. | F25: Exploit protection in Windows 10 enables mitigations against potential threats at the system and application level. Several mitigations, including "Data Execution Prevention (DEP)", are enabled by default at the system level. DEP prevents code from being run from data-only memory pages. If this is turned off, Windows 10 may be subject to various exploits. | G25: This is NA prior to v1709 of Windows 10. This is applicable to unclassified systems, for other systems this is NA. The default configuration in Exploit Protection is "On by default" which meets this requirement. The PowerShell query results for this show as "NOTSET". Run "Windows PowerShell" with elevated privileges (run as administrator). Enter "Get-ProcessMitigation -System". If the status of "DEP: Enable" is "OFF", this is a finding. Values that would not be a finding include: ON NOTSET (Default configuration) | H25: Ensure Exploit Protection system-level mitigation, "Data Execution Prevention (DEP)", is turned on. The default configuration in Exploit Protection is "On by default" which meets this requirement. Open "Windows Defender Security Center". Select "App & browser control". Select "Exploit protection settings". Under "System settings", configure "Data Execution Prevention (DEP)" to "On by default" or "Use default (<On>)". The STIG package includes a DoD EP XML file in the "Supporting Files" folder for configuring application mitigations defined in the STIG. This can also be modified to explicitly enforce the system level requirements. Adding the following to the XML file will explicitly turn DEP on (other system level EP requirements can be combined under <SystemConfig>): <SystemConfig> <DEP Enable="true"></DEP> </SystemConfig> The XML file is applied with the group policy setting Computer Configuration >> Administrative Settings >> Windows Components >> Windows Defender Exploit Guard >> Exploit Protection >> "Use a common set of exploit protection settings" configured to "Enabled" with file name and location defined under "Options:". It is recommended the file be in a read-only network location. | I25: Windows 10 Security Technical Implementation Guide :: Version 2, Release: 2 Benchmark Date: 04 May 2021 | J25: Not Reviewed | L25: CM-6 b | M25: V-77091; SV-91787 | N25: V-77091 | O25: SV-91787 | P25: V-77091
A26: V-77095 | B26: 220874 | C26: V-220874 | D26: SV-220874r569187_rule | E26: Windows 10 Exploit Protection system-level mitigation, Randomize memory allocations (Bottom-Up ASLR), must be on. | F26: Exploit protection in Windows 10 enables mitigations against potential threats at the system and application level. Several mitigations, including "Randomize memory allocations (Bottom-Up ASLR)", are enabled by default at the system level. Bottom-Up ASLR (address space layout randomization) randomizes locations for virtual memory allocations, including those for system structures. If this is turned off, Windows 10 may be subject to various exploits. | G26: This is NA prior to v1709 of Windows 10. This is applicable to unclassified systems, for other systems this is NA. The default configuration in Exploit Protection is "On by default" which meets this requirement. The PowerShell query results for this show as "NOTSET". Run "Windows PowerShell" with elevated privileges (run as administrator). Enter "Get-ProcessMitigation -System". If the status of "ASLR: BottomUp" is "OFF", this is a finding. Values that would not be a finding include: ON NOTSET (Default configuration) | H26: Ensure Exploit Protection system-level mitigation, "Randomize memory allocations (Bottom-Up ASLR)" is turned on. The default configuration in Exploit Protection is "On by default" which meets this requirement. Open "Windows Defender Security Center". Select "App & browser control". Select "Exploit protection settings". Under "System settings", configure "Randomize memory allocations (Bottom-Up ASLR)" to "On by default" or "Use default (<On>)". The STIG package includes a DoD EP XML file in the "Supporting Files" folder for configuring application mitigations defined in the STIG. This can also be modified to explicitly enforce the system level requirements. Adding the following to the XML file will explicitly turn Bottom-Up ASLR on (other system level EP requirements can be combined under <SystemConfig>): <SystemConfig> <ASLR BottomUp="true"</ASLR> </SystemConfig> The XML file is applied with the group policy setting Computer Configuration >> Administrative Settings >> Windows Components >> Windows Defender Exploit Guard >> Exploit Protection >> "Use a common set of exploit protection settings" configured to "Enabled" with file name and location defined under "Options:". It is recommended the file be in a read-only network location. | I26: Windows 10 Security Technical Implementation Guide :: Version 2, Release: 2 Benchmark Date: 04 May 2021 | J26: Not Reviewed | L26: SI-16 | M26: V-77095; SV-91791 | N26: V-77095 | O26: SV-91791 | P26: V-77095
A27: V-77097 | B27: 220875 | C27: V-220875 | D27: SV-220875r569187_rule | E27: Windows 10 Exploit Protection system-level mitigation, Control flow guard (CFG), must be on. | F27: Exploit protection in Windows 10 enables mitigations against potential threats at the system and application level. Several mitigations, including "Control flow guard (CFG)", are enabled by default at the system level. CFG ensures flow integrity for indirect calls. If this is turned off, Windows 10 may be subject to various exploits. | G27: This is NA prior to v1709 of Windows 10. This is applicable to unclassified systems, for other systems this is NA. The default configuration in Exploit Protection is "On by default" which meets this requirement. The PowerShell query results for this show as "NOTSET". Run "Windows PowerShell" with elevated privileges (run as administrator). Enter "Get-ProcessMitigation -System". If the status of "CFG: Enable" is "OFF", this is a finding. Values that would not be a finding include: ON NOTSET (Default configuration) | H27: Ensure Exploit Protection system-level mitigation, "Control flow guard (CFG)", is turned on. The default configuration in Exploit Protection is "On by default" which meets this requirement. Open "Windows Defender Security Center". Select "App & browser control". Select "Exploit protection settings". Under "System settings", configure "Control flow guard (CFG)" to "On by default" or "Use default (<On>)". The STIG package includes a DoD EP XML file in the "Supporting Files" folder for configuring application mitigations defined in the STIG. This can also be modified to explicitly enforce the system level requirements. Adding the following to the XML file will explicitly turn CFG on (other system level EP requirements can be combined under <SystemConfig>): <SystemConfig> <ControlFlowGuard Enable="true"></ControlFlowGuard> </SystemConfig> The XML file is applied with the group policy setting Computer Configuration >> Administrative Settings >> Windows Components >> Windows Defender Exploit Guard >> Exploit Protection >> "Use a common set of exploit protection settings" configured to "Enabled" with file name and location defined under "Options:". It is recommended the file be in a read-only network location. | I27: Windows 10 Security Technical Implementation Guide :: Version 2, Release: 2 Benchmark Date: 04 May 2021 | J27: Not Reviewed | L27: CM-6 b | M27: V-77097; SV-91793 | N27: V-77097 | O27: SV-91793 | P27: V-77097
A28: V-77101 | B28: 220876 | C28: V-220876 | D28: SV-220876r569187_rule | E28: Windows 10 Exploit Protection system-level mitigation, Validate exception chains (SEHOP), must be on. | F28: Exploit protection in Windows 10 enables mitigations against potential threats at the system and application level. Several mitigations, including "Validate exception chains (SEHOP)", are enabled by default at the system level. SEHOP (structured exception handling overwrite protection) ensures the integrity of an exception chain during exception dispatch. If this is turned off, Windows 10 may be subject to various exploits. | G28: This is NA prior to v1709 of Windows 10. This is applicable to unclassified systems, for other systems this is NA. The default configuration in Exploit Protection is "On by default" which meets this requirement. The PowerShell query results for this show as "NOTSET". Run "Windows PowerShell" with elevated privileges (run as administrator). Enter "Get-ProcessMitigation -System". If the status of "SEHOP: Enable" is "OFF", this is a finding. Values that would not be a finding include: ON NOTSET (Default configuration) | H28: Ensure Exploit Protection system-level mitigation, "Validate exception chains (SEHOP)", is turned on. The default configuration in Exploit Protection is "On by default" which meets this requirement. Open "Windows Defender Security Center". Select "App & browser control". Select "Exploit protection settings". Under "System settings", configure "Validate exception chains (SEHOP)" to "On by default" or "Use default (<On>)". The STIG package includes a DoD EP XML file in the "Supporting Files" folder for configuring application mitigations defined in the STIG. This can also be modified to explicitly enforce the system level requirements. Adding the following to the XML file will explicitly turn SEHOP on (other system level EP requirements can be combined under <SystemConfig>): <SystemConfig> <SEHOP Enable="true"></SEHOP> </SystemConfig> The XML file is applied with the group policy setting Computer Configuration >> Administrative Settings >> Windows Components >> Windows Defender Exploit Guard >> Exploit Protection >> "Use a common set of exploit protection settings" configured to "Enabled" with file name and location defined under "Options:". It is recommended the file be in a read-only network location. | I28: Windows 10 Security Technical Implementation Guide :: Version 2, Release: 2 Benchmark Date: 04 May 2021 | J28: Not Reviewed | L28: CM-6 b | M28: V-77101; SV-91797 | N28: V-77101 | O28: SV-91797 | P28: V-77101
A29: V-77103 | B29: 220877 | C29: V-220877 | D29: SV-220877r569187_rule | E29: Windows 10 Exploit Protection system-level mitigation, Validate heap integrity, must be on. | F29: Exploit protection in Windows 10 enables mitigations against potential threats at the system and application level. Several mitigations, including "Validate heap integrity", are enabled by default at the system level. "Validate heap integrity" terminates a process when heap corruption is detected. If this is turned off, Windows 10 may be subject to various exploits. | G29: This is NA prior to v1709 of Windows 10. This is applicable to unclassified systems, for other systems this is NA. The default configuration in Exploit Protection is "On by default" which meets this requirement. The PowerShell query results for this show as "NOTSET". Run "Windows PowerShell" with elevated privileges (run as administrator). Enter "Get-ProcessMitigation -System". If the status of "Heap: TerminateOnError" is "OFF", this is a finding. Values that would not be a finding include: ON NOTSET (Default configuration) | H29: Ensure Exploit Protection system-level mitigation, "Validate heap integrity" is turned on. The default configuration in Exploit Protection is "On by default" which meets this requirement. Open "Windows Defender Security Center". Select "App & browser control". Select "Exploit protection settings". Under "System settings", configure "Validate heap integrity" to "On by default" or "Use default (<On>)". The STIG package includes a DoD EP XML file in the "Supporting Files" folder for configuring application mitigations defined in the STIG. This can also be modified to explicitly enforce the system level requirements. Adding the following to the XML file will explicitly turn Validate heap integrity on (other system level EP requirements can be combined under <SystemConfig>): <SystemConfig> <Heap TerminateOnError="true"></Heap> </SystemConfig> The XML file is applied with the group policy setting Computer Configuration >> Administrative Settings >> Windows Components >> Windows Defender Exploit Guard >> Exploit Protection >> "Use a common set of exploit protection settings" configured to "Enabled" with file name and location defined under "Options:". It is recommended the file be in a read-only network location. | I29: Windows 10 Security Technical Implementation Guide :: Version 2, Release: 2 Benchmark Date: 04 May 2021 | J29: Not Reviewed | L29: CM-6 b | M29: V-77103; SV-91799 | N29: V-77103 | O29: SV-91799 | P29: V-77103
A30: V-77189 | B30: 220878 | C30: V-220878 | D30: SV-220878r569187_rule | E30: Exploit Protection mitigations in Windows 10 must be configured for Acrobat.exe. | F30: Exploit protection in Windows 10 provides a means of enabling additional mitigations against potential threats at the system and application level. Without these additional application protections, Windows 10 may be subject to various exploits. | G30: This is NA prior to v1709 of Windows 10. This is applicable to unclassified systems, for other systems this is NA. Run "Windows PowerShell" with elevated privileges (run as administrator). Enter "Get-ProcessMitigation -Name Acrobat.exe". (Get-ProcessMitigation can be run without the -Name parameter to get a list of all application mitigations configured.) If the following mitigations do not have the listed status which is shown below, this is a finding: DEP: Override DEP: False ASLR: ForceRelocateImages: ON Payload: OverrideExportAddressFilter: False OverrideExportAddressFilterPlus: False OverrideImportAddressFilter: False OverrideEnableRopStackPivot: False OverrideEnableRopCallerCheck: False OverrideEnableRopSimExec: False The PowerShell command produces a list of mitigations; only those with a required status of are listed here. If the PowerShell command does not produce results, ensure the letter case of the filename within the command syntax matches the letter case of the actual filename on the system. | H30: Ensure the following mitigations are configured as shown for Acrobat.exe: DEP: Override DEP: False ASLR: ForceRelocateImages: ON Payload: OverrideExportAddressFilter: False OverrideExportAddressFilterPlus: False OverrideImportAddressFilter: False OverrideEnableRopStackPivot: False OverrideEnableRopCallerCheck: False OverrideEnableRopSimExec: False Application mitigations defined in the STIG are configured by a DoD EP XML file included with the Windows 10 STIG package in the "Supporting Files" folder. The XML file is applied with the group policy setting Computer Configuration >> Administrative Settings >> Windows Components >> Windows Defender Exploit Guard >> Exploit Protection >> "Use a common set of exploit protection settings" configured to "Enabled" with file name and location defined under "Options:". It is recommended the file be in a read-only network location. | I30: Windows 10 Security Technical Implementation Guide :: Version 2, Release: 2 Benchmark Date: 04 May 2021 | J30: Not Reviewed | L30: CM-6 b | M30: V-77189; SV-91885 | N30: V-77189 | O30: SV-91885 | P30: V-77189
A31: V-77191 | B31: 220879 | C31: V-220879 | D31: SV-220879r569187_rule | E31: Exploit Protection mitigations in Windows 10 must be configured for AcroRd32.exe. | F31: Exploit protection in Windows 10 provides a means of enabling additional mitigations against potential threats at the system and application level. Without these additional application protections, Windows 10 may be subject to various exploits. | G31: This is NA prior to v1709 of Windows 10. This is applicable to unclassified systems, for other systems this is NA. Run "Windows PowerShell" with elevated privileges (run as administrator). Enter "Get-ProcessMitigation -Name AcroRd32.exe". (Get-ProcessMitigation can be run without the -Name parameter to get a list of all application mitigations configured.) If the following mitigations do not have the listed status which is shown below, this is a finding: DEP: Override DEP: False ASLR: ForceRelocateImages: ON Payload: OverrideExportAddressFilter: False OverrideExportAddressFilterPlus: False OverrideImportAddressFilter: False OverrideEnableRopStackPivot= False OverrideEnableRopCallerCheck: False OverrideEnableRopSimExec: False The PowerShell command produces a list of mitigations; only those with a required status are listed here. If the PowerShell command does not produce results, ensure the letter case of the filename within the command syntax matches the letter case of the actual filename on the system. | H31: Ensure the following mitigations are configured as shown for AcroRd32.exe: DEP: Override DEP: False ASLR: ForceRelocateImages: ON Payload: OverrideExportAddressFilter: False OverrideExportAddressFilterPlus: False OverrideImportAddressFilter: False OverrideEnableRopStackPivot= False OverrideEnableRopCallerCheck: False OverrideEnableRopSimExec: False Application mitigations defined in the STIG are configured by a DoD EP XML file included with the Windows 10 STIG package in the "Supporting Files" folder. The XML file is applied with the group policy setting Computer Configuration >> Administrative Settings >> Windows Components >> Windows Defender Exploit Guard >> Exploit Protection >> "Use a common set of exploit protection settings" configured to "Enabled" with file name and location defined under "Options:". It is recommended the file be in a read-only network location. | I31: Windows 10 Security Technical Implementation Guide :: Version 2, Release: 2 Benchmark Date: 04 May 2021 | J31: Not Reviewed | L31: CM-6 b | M31: V-77191; SV-91887 | N31: V-77191 | O31: SV-91887 | P31: V-77191
A32: V-77195 | B32: 220880 | C32: V-220880 | D32: SV-220880r569187_rule | E32: Exploit Protection mitigations in Windows 10 must be configured for chrome.exe. | F32: Exploit protection in Windows 10 provides a means of enabling additional mitigations against potential threats at the system and application level. Without these additional application protections, Windows 10 may be subject to various exploits. | G32: This is NA prior to v1709 of Windows 10. This is applicable to unclassified systems, for other systems this is NA. Run "Windows PowerShell" with elevated privileges (run as administrator). Enter "Get-ProcessMitigation -Name chrome.exe". (Get-ProcessMitigation can be run without the -Name parameter to get a list of all application mitigations configured.) If the following mitigations do not have the listed status which is shown below, this is a finding: DEP: OverrideDEP: False The PowerShell command produces a list of mitigations; only those with a required status are listed here. If the PowerShell command does not produce results, ensure the letter case of the filename within the command syntax matches the letter case of the actual filename on the system. | H32: Ensure the following mitigations are configured as shown forchrome.exe: DEP: OverrideDEP: False Application mitigations defined in the STIG are configured by a DoD EP XML file included with the Windows 10 STIG package in the "Supporting Files" folder. The XML file is applied with the group policy setting Computer Configuration >> Administrative Settings >> Windows Components >> Windows Defender Exploit Guard >> Exploit Protection >> "Use a common set of exploit protection settings" configured to "Enabled" with file name and location defined under "Options:". It is recommended the file be in a read-only network location. | I32: Windows 10 Security Technical Implementation Guide :: Version 2, Release: 2 Benchmark Date: 04 May 2021 | J32: Not Reviewed | L32: CM-6 b | M32: V-77195; SV-91891 | N32: V-77195 | O32: SV-91891 | P32: V-77195
A33: V-77201 | B33: 220881 | C33: V-220881 | D33: SV-220881r569187_rule | E33: Exploit Protection mitigations in Windows 10 must be configured for EXCEL.EXE. | F33: Exploit protection in Windows 10 provides a means of enabling additional mitigations against potential threats at the system and application level. Without these additional application protections, Windows 10 may be subject to various exploits. | G33: This is NA prior to v1709 of Windows 10. This is applicable to unclassified systems, for other systems this is NA. Run "Windows PowerShell" with elevated privileges (run as administrator). Enter "Get-ProcessMitigation -Name EXCEL.EXE". (Get-ProcessMitigation can be run without the -Name parameter to get a list of all application mitigations configured.) If the following mitigations do not have the listed status which is shown below, this is a finding: DEP: Override DEP: False ASLR: ForceRelocateImages: ON Payload: OverrideExportAddressFilter: False OverrideExportAddressFilterPlus: False OverrideImportAddressFilter: False OverrideEnableRopStackPivot: False OverrideEnableRopCallerCheck: False OverrideEnableRopSimExec: False The PowerShell command produces a list of mitigations; only those with a required status are listed here. If the PowerShell command does not produce results, ensure the letter case of the filename within the command syntax matches the letter case of the actual filename on the system. | H33: Ensure the following mitigations are configured as shown for EXCEL.EXE: DEP: Override DEP: False ASLR: ForceRelocateImages: ON Payload: OverrideExportAddressFilter: False OverrideExportAddressFilterPlus: False OverrideImportAddressFilter: False OverrideEnableRopStackPivot: False OverrideEnableRopCallerCheck: False OverrideEnableRopSimExec: False Application mitigations defined in the STIG are configured by a DoD EP XML file included with the Windows 10 STIG package in the "Supporting Files" folder. The XML file is applied with the group policy setting Computer Configuration >> Administrative Settings >> Windows Components >> Windows Defender Exploit Guard >> Exploit Protection >> "Use a common set of exploit protection settings" configured to "Enabled" with file name and location defined under "Options:". It is recommended the file be in a read-only network location. | I33: Windows 10 Security Technical Implementation Guide :: Version 2, Release: 2 Benchmark Date: 04 May 2021 | J33: Not Reviewed | L33: CM-6 b | M33: V-77201; SV-91897 | N33: V-77201 | O33: SV-91897 | P33: V-77201
A34: V-77205 | B34: 220882 | C34: V-220882 | D34: SV-220882r569187_rule | E34: Exploit Protection mitigations in Windows 10 must be configured for firefox.exe. | F34: Exploit protection in Windows 10 provides a means of enabling additional mitigations against potential threats at the system and application level. Without these additional application protections, Windows 10 may be subject to various exploits. | G34: This is NA prior to v1709 of Windows 10. This is applicable to unclassified systems, for other systems this is NA. Run "Windows PowerShell" with elevated privileges (run as administrator). Enter "Get-ProcessMitigation -Name firefox.exe". (Get-ProcessMitigation can be run without the -Name parameter to get a list of all application mitigations configured.) If the following mitigations do not have the listed status which is shown below, this is a finding: DEP: Override DEP: False ASLR: ForceRelocateImages: On The PowerShell command produces a list of mitigations; only those with a required status are listed here. If the PowerShell command does not produce results, ensure the letter case of the filename within the command syntax matches the letter case of the actual filename on the system. | H34: Ensure the following mitigations are configured as shown firefox.exe: DEP: Override DEP: False ASLR: ForceRelocateImages: On Application mitigations defined in the STIG are configured by a DoD EP XML file included with the Windows 10 STIG package in the "Supporting Files" folder. The XML file is applied with the group policy setting Computer Configuration >> Administrative Settings >> Windows Components >> Windows Defender Exploit Guard >> Exploit Protection >> "Use a common set of exploit protection settings" configured to "Enabled" with file name and location defined under "Options:". It is recommended the file be in a read-only network location. | I34: Windows 10 Security Technical Implementation Guide :: Version 2, Release: 2 Benchmark Date: 04 May 2021 | J34: Not Reviewed | L34: CM-6 b | M34: V-77205; SV-91901 | N34: V-77205 | O34: SV-91901 | P34: V-77205
A35: V-77209 | B35: 220883 | C35: V-220883 | D35: SV-220883r569187_rule | E35: Exploit Protection mitigations in Windows 10 must be configured for FLTLDR.EXE. | F35: Exploit protection in Windows 10 provides a means of enabling additional mitigations against potential threats at the system and application level. Without these additional application protections, Windows 10 may be subject to various exploits. | G35: This is NA prior to v1709 of Windows 10. This is applicable to unclassified systems, for other systems this is NA. Run "Windows PowerShell" with elevated privileges (run as administrator). Enter "Get-ProcessMitigation -Name FLTLDR.EXE". (Get-ProcessMitigation can be run without the -Name parameter to get a list of all application mitigations configured.) If the following mitigations do not have the listed status which is shown below, this is a finding: DEP: Override DEP: False ImageLoad: OverrideBlockRemoteImages: False Payload: OverrideExportAddressFilter: False OverrideExportAddressFilterPlus: False OverrideImportAddressFilter: False OverrideEnableRopStackPivot: False OverrideEnableRopCallerCheck: False OverrideEnableRopSimExec: False Child Process: OverrideChildProcess: False The PowerShell command produces a list of mitigations; only those with a required status are listed here. If the PowerShell command does not produce results, ensure the letter case of the filename within the command syntax matches the letter case of the actual filename on the system. | H35: Ensure the following mitigations are configured as shown for FLTLDR.EXE: DEP: Override DEP: False ImageLoad: OverrideBlockRemoteImages: False Payload: OverrideExportAddressFilter: False OverrideExportAddressFilterPlus: False OverrideImportAddressFilter: False OverrideEnableRopStackPivot: False OverrideEnableRopCallerCheck: False OverrideEnableRopSimExec: False Child Process: OverrideChildProcess: False Application mitigations defined in the STIG are configured by a DoD EP XML file included with the Windows 10 STIG package in the "Supporting Files" folder. The XML file is applied with the group policy setting Computer Configuration >> Administrative Settings >> Windows Components >> Windows Defender Exploit Guard >> Exploit Protection >> "Use a common set of exploit protection settings" configured to "Enabled" with file name and location defined under "Options:". It is recommended the file be in a read-only network location. | I35: Windows 10 Security Technical Implementation Guide :: Version 2, Release: 2 Benchmark Date: 04 May 2021 | J35: Not Reviewed | L35: CM-6 b | M35: V-77209; SV-91905 | N35: V-77209 | O35: SV-91905 | P35: V-77209
A36: V-77213 | B36: 220884 | C36: V-220884 | D36: SV-220884r569187_rule | E36: Exploit Protection mitigations in Windows 10 must be configured for GROOVE.EXE. | F36: Exploit protection in Windows 10 provides a means of enabling additional mitigations against potential threats at the system and application level. Without these additional application protections, Windows 10 may be subject to various exploits. | G36: This is NA prior to v1709 of Windows 10. This is applicable to unclassified systems, for other systems this is NA. Run "Windows PowerShell" with elevated privileges (run as administrator). Enter "Get-ProcessMitigation -Name GROOVE.EXE". (Get-ProcessMitigation can be run without the -Name parameter to get a list of all application mitigations configured.) If the following mitigations do not have the listed status which is shown below, this is a finding: DEP: OverrideDEP: False ASLR: ForceRelocateImages: On ImageLoad: OverrideBlockRemoteImages: False Payload: OverrideExportAddressFilter: False OverrideExportAddressFilterPlus: False OverrideImportAddressFilter: False OverrideEnableRopStackPivot: False OverrideEnableRopCallerCheck: False OverrideEnableRopSimExec: False Child Process: OverrideChildProcess: False The PowerShell command produces a list of mitigations; only those with a required status are listed here. If the PowerShell command does not produce results, ensure the letter case of the filename within the command syntax matches the letter case of the actual filename on the system. | H36: Ensure the following mitigations are configured as shown GROOVE.EXE: DEP: OverrideDEP: False ASLR: OverrideBlockRemoteImages: False ImageLoad: ForceRelocateImages: True Payload: OverrideExportAddressFilter: False OverrideExportAddressFilterPlus: False OverrideImportAddressFilter: False OverrideEnableRopStackPivot: False OverrideEnableRopCallerCheck: False OverrideEnableRopSimExec: False Child Process: OverrideChildProcess: False Application mitigations defined in the STIG are configured by a DoD EP XML file included with the Windows 10 STIG package in the "Supporting Files" folder. The XML file is applied with the group policy setting Computer Configuration >> Administrative Settings >> Windows Components >> Windows Defender Exploit Guard >> Exploit Protection >> "Use a common set of exploit protection settings" configured to "Enabled" with file name and location defined under "Options:". It is recommended the file be in a read-only network location. | I36: Windows 10 Security Technical Implementation Guide :: Version 2, Release: 2 Benchmark Date: 04 May 2021 | J36: Not Reviewed | L36: CM-6 b | M36: V-77213; SV-91909 | N36: V-77213 | O36: SV-91909 | P36: V-77213
... A41: V-77231 | B41: 220889 | C41: V-220889 | D41: SV-220889r569187_rule | E41: Exploit Protection mitigations in Windows 10 must be configured for MSACCESS.EXE. | F41: Exploit protection in Windows 10 provides a means of enabling additional mitigations against potential threats at the system and application level. Without these additional application protections, Windows 10 may be subject to various exploits. | G41: This is NA prior to v1709 of Windows 10. This is applicable to unclassified systems, for other systems this is NA. Run "Windows PowerShell" with elevated privileges (run as administrator). Enter "Get-ProcessMitigation -Name MSACCESS.EXE". (Get-ProcessMitigation can be run without the -Name parameter to get a list of all application mitigations configured.) If the following mitigations do not have the listed status which is shown below, this is a finding: DEP: Override DEP: False ASLR: ForceRelocateImages: ON Payload: OverrideExportAddressFilter: False OverrideExportAddressFilterPlus: False OverrideImportAddressFilter: False OverrideEnableRopStackPivot: False OverrideEnableRopCallerCheck: False OverrideEnableRopSimExec: False The PowerShell command produces a list of mitigations; only those with a required status of are listed here. If the PowerShell command does not produce results, ensure the letter case of the filename within the command syntax matches the letter case of the actual filename on the system. | H41: Ensure the following mitigations are configured as shown for MSACCESS.EXE: DEP: Override DEP: False ASLR: ForceRelocateImages: ON Payload: OverrideExportAddressFilter: False OverrideExportAddressFilterPlus: False OverrideImportAddressFilter: False OverrideEnableRopStackPivot: False OverrideEnableRopCallerCheck: False OverrideEnableRopSimExec: False Application mitigations defined in the STIG are configured by a DoD EP XML file included with the Windows 10 STIG package in the "Supporting Files" folder. The XML file is applied with the group policy setting Computer Configuration >> Administrative Settings >> Windows Components >> Windows Defender Exploit Guard >> Exploit Protection >> "Use a common set of exploit protection settings" configured to "Enabled" with file name and location defined under "Options:". It is recommended the file be in a read-only network location. | I41: Windows 10 Security Technical Implementation Guide :: Version 2, Release: 2 Benchmark Date: 04 May 2021 | J41: Not Reviewed | L41: CM-6 b | M41: V-77231; SV-91927 | N41: V-77231 | O41: SV-91927 | P41: V-77231
A42: V-77233 | B42: 220890 | C42: V-220890 | D42: SV-220890r569187_rule | E42: Exploit Protection mitigations in Windows 10 must be configured for MSPUB.EXE. | F42: Exploit protection in Windows 10 provides a means of enabling additional mitigations against potential threats at the system and application level. Without these additional application protections, Windows 10 may be subject to various exploits. | G42: This is NA prior to v1709 of Windows 10. This is applicable to unclassified systems, for other systems this is NA. Run "Windows PowerShell" with elevated privileges (run as administrator). Enter "Get-ProcessMitigation -Name MSPUB.EXE". (Get-ProcessMitigation can be run without the -Name parameter to get a list of all application mitigations configured.) If the following mitigations do not have the listed status which is shown below, this is a finding: DEP: Override DEP: False ASLR: ForceRelocateImages: ON Payload: OverrideExportAddressFilter: False OverrideExportAddressFilterPlus: False OverrideImportAddressFilter: False OverrideEnableRopStackPivot: False OverrideEnableRopCallerCheck: False OverrideEnableRopSimExec: False The PowerShell command produces a list of mitigations; only those with a required status are listed here. If the PowerShell command does not produce results, ensure the letter case of the filename within the command syntax matches the letter case of the actual filename on the system. | H42: Ensure the following mitigations are configured as shown for MSPUB.EXE: DEP: Override DEP: False ASLR: ForceRelocateImages: ON Payload: OverrideExportAddressFilter: False OverrideExportAddressFilterPlus: False OverrideImportAddressFilter: False OverrideEnableRopStackPivot: False OverrideEnableRopCallerCheck: False OverrideEnableRopSimExec: False Application mitigations defined in the STIG are configured by a DoD EP XML file included with the Windows 10 STIG package in the "Supporting Files" folder. The XML file is applied with the group policy setting Computer Configuration >> Administrative Settings >> Windows Components >> Windows Defender Exploit Guard >> Exploit Protection >> "Use a common set of exploit protection settings" configured to "Enabled" with file name and location defined under "Options:". It is recommended the file be in a read-only network location. | I42: Windows 10 Security Technical Implementation Guide :: Version 2, Release: 2 Benchmark Date: 04 May 2021 | J42: Not Reviewed | L42: CM-6 b | M42: V-77233; SV-91929 | N42: V-77233 | O42: SV-91929 | P42: V-77233
